<mujoco model="00_arm_rs_asm_v3">
  <compiler angle="radian" meshdir="meshes/" />
  <asset>
    <mesh name="base_link" file="base_link.STL" />
    <mesh name="link1" file="link1.STL" />
    <mesh name="motor_2_3" file="motor_2_3.STL" />
    <mesh name="cnc2" file="cnc2.STL" />
    <mesh name="pla2_black" file="pla2_black.STL" />
    <mesh name="pla2_green" file="pla2_green.STL" />
    <mesh name="link2" file="link2.STL" />
    <mesh name="cnc3" file="cnc3.STL" />
    <mesh name="motor_4" file="motor_4.STL" />
    <mesh name="pla3_black" file="pla3_black.STL" />
    <mesh name="pla3_green" file="pla3_green.STL" />
    <mesh name="link3" file="link3.STL" />
    <mesh name="motor_5" file="motor_5.STL" />
    <mesh name="cnc4" file="cnc4.STL" />
    <mesh name="link4" file="link4.STL" />
    <mesh name="motor_6" file="motor_6.STL" />
    <mesh name="cnc5" file="cnc5.STL" />
    <mesh name="pla5_green" file="pla5_green.STL" />
    <mesh name="link5" file="link5.STL" />
    <mesh name="link6" file="link6.STL" />
    <mesh name="pla7_green" file="pla7_green.STL" />
    <mesh name="cnc7" file="cnc7.STL" />
    <mesh name="motor_7" file="motor_7.STL" />
    <mesh name="gripper_end" file="gripper_end.STL" />
    <mesh name="pla_left" file="pla_left.STL" />
    <mesh name="cnc_left" file="cnc_left.STL" />
    <mesh name="pla_right" file="pla_right.STL" />
    <mesh name="cnc_right" file="cnc_right.STL" />
    <material name="base_link_mat" rgba="0.7529 0.7529 0.7529 1" specular="0" />
    <material name="link1_mat" rgba="0.7529 0.7529 0.7529 1" specular="0" />
    <material name="link2_mat" rgba="0.7529 0.7529 0.7529 1" specular="0" />
    <material name="link2_mat_2" rgba="0.7529 0.7529 0.7529 1" />
    <material name="link2_mat_3" rgba="0.7529 0.7529 0.7529 1" />
    <material name="link2_mat_4" rgba="0.7529 0.7529 0.7529 1" />
    <material name="link3_mat" rgba="0.7529 0.7529 0.7529 1" specular="0" />
    <material name="link3_mat_2" rgba="0.7529 0.7529 0.7529 1" />
    <material name="link3_mat_3" rgba="0.7529 0.7529 0.7529 1" />
    <material name="link3_mat_4" rgba="0.7529 0.7529 0.7529 1" />
    <material name="link4_mat" rgba="0.7529 0.7529 0.7529 1" specular="0" />
    <material name="link4_mat_2" rgba="0.7529 0.7529 0.7529 1" />
    <material name="link5_mat" rgba="0.7529 0.7529 0.7529 1" specular="0" />
    <material name="link5_mat_2" rgba="0.7529 0.7529 0.7529 1" />
    <material name="link5_mat_3" rgba="0.7529 0.7529 0.7529 1" />
    <material name="link6_mat" rgba="0.7529 0.7529 0.7529 1" specular="0" />
    <material name="gripper_end_mat" rgba="0.7529 0.7529 0.7529 1" specular="0" />
    <material name="gripper_end_mat_2" rgba="0.7529 0.7529 0.7529 1" />
    <material name="gripper_end_mat_3" rgba="0.7529 0.7529 0.7529 1" />
    <material name="gripper_left_mat" rgba="0.7529 0.7529 0.7529 1" specular="0" />
    <material name="gripper_left_mat_2" rgba="0.7529 0.7529 0.7529 1" />
    <material name="gripper_right_mat" rgba="0.7529 0.7529 0.7529 1" specular="0" />
    <material name="gripper_right_mat_2" rgba="0.7529 0.7529 0.7529 1" />
  </asset>

  <worldbody>
    <body name="base_link" pos="0 0 0">
      <inertial pos="0.0000029 -0.0001223 0.0243376" mass="1.1774" fullinertia="0.0013304 0.00213119 0.00275877 0.00000001 0 0"/>
      <geom pos="0 0 0" group="1" contype="0" conaffinity="0" material="base_link_mat" type="mesh" mesh="base_link" />
      <geom pos="0 0 0" rgba="0.9373 0.2667 0.2667 1" group="3" contype="1" conaffinity="1" type="mesh" mesh="base_link" />
      <body name="link1" pos="-0.0003428 -0.0009868 0.075">
        <joint name="joint1" type="hinge" axis="0 0 -1" limited="true" range="-2.8 2.8" damping="0.5" frictionloss="0"/>
        <inertial pos="0.0081765 0.0012258 0.033142" mass="0.4655" fullinertia="0.00025207 0.00015464 0.00023416 0 -0.00002832 0"/>
        <geom pos="0 0 0" group="1" contype="0" conaffinity="0" material="link1_mat" type="mesh" mesh="link1" />
        <geom pos="0 0 0" rgba="0.9373 0.2667 0.2667 1" group="3" contype="1" conaffinity="1" type="mesh" mesh="link1" />
        <body name="link2" pos="0.020343 0.027237 0.07" quat="0.7071055 -0.7071081 0 0">
          <joint name="joint2" type="hinge" axis="0 0 1" limited="true" range="0 3.14" damping="0.5" frictionloss="0"/>
          <inertial pos="-0.1178648 -0.0034223 -0.0271552" mass="1.772" fullinertia="0.00073374 0.01255987 0.01281387 -0.00000043 0.00000851 0.00000128"/>
          <geom pos="0 0 0" group="1" contype="0" conaffinity="0" material="link2_mat" type="mesh" mesh="motor_2_3" />
          <geom pos="0 0 0" group="1" contype="0" conaffinity="0" material="link2_mat_2" type="mesh" mesh="cnc2" />
          <geom pos="0 0 0" group="1" contype="0" conaffinity="0" material="link2_mat_3" type="mesh" mesh="pla2_black" />
          <geom pos="0 0 0" group="1" contype="0" conaffinity="0" material="link2_mat_4" type="mesh" mesh="pla2_green" />
          <geom pos="0 0 0" rgba="0.9373 0.2667 0.2667 1" group="3" contype="1" conaffinity="1" type="mesh" mesh="link2" />
          <body name="link3" pos="-0.236 0 0">
            <joint name="joint3" type="hinge" axis="0 0 -1" limited="true" range="0 3.14" damping="0.5" frictionloss="0"/>
            <inertial pos="0.1034272 -0.0664138 -0.0271069" mass="1.062" fullinertia="0.00046807 0.00632695 0.00648221 -0.00003456 -0.0000426 0.00000006"/>
            <geom pos="0 0 0" group="1" contype="0" conaffinity="0" material="link3_mat" type="mesh" mesh="cnc3" />
            <geom pos="0 0 0" group="1" contype="0" conaffinity="0" material="link3_mat_2" type="mesh" mesh="motor_4" />
            <geom pos="0 0 0" group="1" contype="0" conaffinity="0" material="link3_mat_3" type="mesh" mesh="pla3_black" />
            <geom pos="0 0 0" group="1" contype="0" conaffinity="0" material="link3_mat_4" type="mesh" mesh="pla3_green" />
            <geom pos="0 0 0" rgba="0.9373 0.2667 0.2667 1" group="3" contype="1" conaffinity="1" type="mesh" mesh="link3" />
            <body name="link4" pos="0.228 -0.072746 0.0045">
              <joint name="joint4" type="hinge" axis="0 0 -1" limited="true" range="-1.57 1.57" damping="0.5" frictionloss="0"/>
              <inertial pos="0.0475545 -0.0441113 -0.0314112" mass="0.66" fullinertia="0.00045986 0.00075258 0.00066742 0.00024219 0 0"/>
              <geom pos="0 0 0" group="1" contype="0" conaffinity="0" material="link4_mat" type="mesh" mesh="motor_5" />
              <geom pos="0 0 0" group="1" contype="0" conaffinity="0" material="link4_mat_2" type="mesh" mesh="cnc4" />
              <geom pos="0 0 0" rgba="0.9373 0.2667 0.2667 1" group="3" contype="1" conaffinity="1" type="mesh" mesh="link4" />
              <body name="link5" pos="0.087 -0.048 -0.03075" quat="0.7071055 -0.7071081 0 0">
                <joint name="joint5" type="hinge" axis="0 0 -1" limited="true" range="-1.57 1.57" damping="0.5" frictionloss="0"/>
                <inertial pos="-0.0114401 0.0000048 0.0480487" mass="0.1501205" fullinertia="0.0000734238 0.0000551539 0.000052992 0.0000000136 -0.0000008581 -0.0000000133"/>
                <geom pos="0 0 0" group="1" contype="0" conaffinity="0" material="link5_mat" type="mesh" mesh="motor_6" />
                <geom pos="0 0 0" group="1" contype="0" conaffinity="0" material="link5_mat_2" type="mesh" mesh="cnc5" />
                <geom pos="0 0 0" group="1" contype="0" conaffinity="0" material="link5_mat_3" type="mesh" mesh="pla5_green" />
                <geom pos="0 0 0" rgba="0.9373 0.2667 0.2667 1" group="3" contype="1" conaffinity="1" type="mesh" mesh="link5" />
                <body name="link6" pos="0.0365 0 0.048" quat="0.7071055 0 0.7071081 0">
                  <joint name="joint6" type="hinge" axis="0 0 -1" limited="true" range="-3.14 3.14" damping="2.0" frictionloss="0.1"/>
                  <inertial pos="0.000018 0 0.0043481" mass="0.03" fullinertia="0.0000044227 0.0000043719 0.000008543 0 0.0000000002 0"/>
                  <geom pos="0 0 0" group="1" contype="0" conaffinity="0" material="link6_mat" type="mesh" mesh="link6" />
                  <geom pos="0 0 0" rgba="0.9373 0.2667 0.2667 1" group="3" contype="1" conaffinity="1" type="mesh" mesh="link6" />
                  <body name="gripper_end" pos="0 0 0.16621" quat="-0.0000026 0.7071055 0.0000026 0.7071081">
                    <inertial pos="-0.1127517 0.0001284 -0.0000057" mass="0.65" fullinertia="0.00037354 0.0001583 0.00045353 -0.00000011 0.0000005 0.00000348"/>
                    <geom pos="0 0 0" group="1" contype="0" conaffinity="0" material="gripper_end_mat" type="mesh" mesh="pla7_green" />
                    <geom pos="0 0 0" group="1" contype="0" conaffinity="0" material="gripper_end_mat_2" type="mesh" mesh="cnc7" />
                    <geom pos="0 0 0" group="1" contype="0" conaffinity="0" material="gripper_end_mat_3" type="mesh" mesh="motor_7" />
                    <geom pos="0 0 0" rgba="0.9373 0.2667 0.2667 1" group="3" contype="1" conaffinity="1" type="mesh" mesh="gripper_end" />
                    <!-- 夹爪驱动关节：通过 equality 与 joint_left / joint_right 联动。
                         axis="0 1 0" 沿 gripper_end 局部 -Y，即世界 Y 负方向，
                         因此 joint7 增大时 left 向 -Y、right 向 +Y 张开。 -->
                    <body name="gripper_coupler" pos="0 0 0">
                      <joint name="joint7" type="slide" axis="0 1 0" limited="true" range="0 0.05" damping="1.0" frictionloss="0.1"/>
                      <inertial pos="0 0 0" mass="0.001" diaginertia="0.000001 0.000001 0.000001"/>
                    </body>
                    <body name="gripper_left" pos="-0.041939 -0.0000734 0" quat="0.4999982 0.5 -0.5 0.5000018">
                      <joint name="joint_left" type="slide" axis="0 0 1" limited="true" range="0 0.05" damping="5.0" frictionloss="0.5"/>
                      <inertial pos="-0.0021801 0.018709 0.0093219" mass="0.0752" diaginertia="0.0000109878 0.0000095015 0.0000093078"/>
                      <geom pos="0 0 0" group="1" contype="0" conaffinity="0" material="gripper_left_mat" type="mesh" mesh="pla_left" />
                      <geom pos="0 0 0" group="1" contype="0" conaffinity="0" material="gripper_left_mat_2" type="mesh" mesh="cnc_left" />
                      <geom pos="0 0 0" rgba="0.9373 0.2667 0.2667 1" group="3" contype="1" conaffinity="1" type="mesh" mesh="pla_left" />
                    </body>
                    <body name="gripper_right" pos="-0.041939 0.0000734 0" quat="0.4999982 -0.5 -0.5 -0.5000018">
                      <joint name="joint_right" type="slide" axis="0 0 1" limited="true" range="0 0.0715" damping="5.0" frictionloss="0.5"/>
                      <inertial pos="0.0021801 -0.018709 0.0093219" mass="0.0752" diaginertia="0.0000109878 0.0000095015 0.0000093078"/>
                      <geom pos="0 0 0" group="1" contype="0" conaffinity="0" material="gripper_right_mat" type="mesh" mesh="pla_right" />
                      <geom pos="0 0 0" group="1" contype="0" conaffinity="0" material="gripper_right_mat_2" type="mesh" mesh="cnc_right" />
                      <geom pos="0 0 0" rgba="0.9373 0.2667 0.2667 1" group="3" contype="1" conaffinity="1" type="mesh" mesh="pla_right" />
                    </body>
                  </body>
                </body>
              </body>
            </body>
          </body>
        </body>
      </body>
    </body>
  </worldbody>
  <equality>
    <!-- joint7 与左右夹爪直线位移 1:1 联动 -->
    <joint joint1="joint7" joint2="joint_left"  polycoef="0 1 0 0 0"/>
    <joint joint1="joint7" joint2="joint_right" polycoef="0 1 0 0 0"/>
  </equality>
  <actuator>
    <position name="joint1_servo" joint="joint1" kp="18" kv="2.0" ctrlrange="-2.8 2.8" forcelimited="true" forcerange="-36 36" />
    <position name="joint2_servo" joint="joint2" kp="18" kv="2.0" ctrlrange="0 3.14" forcelimited="true" forcerange="-36 36" />
    <position name="joint3_servo" joint="joint3" kp="18" kv="2.0" ctrlrange="0 3.14" forcelimited="true" forcerange="-36 36" />
    <position name="joint4_servo" joint="joint4" kp="7" kv="1.0" ctrlrange="-1.57 1.57" forcelimited="true" forcerange="-14 14" />
    <position name="joint5_servo" joint="joint5" kp="7" kv="1.0" ctrlrange="-1.57 1.57" forcelimited="true" forcerange="-14 14" />
    <position name="joint6_servo" joint="joint6" kp="7" kv="1.0" ctrlrange="-3.14 3.14" forcelimited="true" forcerange="-14 14" />
    <!-- Gripper actuators disabled: in real-to-sim the gripper is driven
         kinematically from the real motor position, so MuJoCo should not
         apply its own servo force (which would create artificial contact
         forces and disturb the grasp feedback). -->
    <!--
    <position name="joint_left_servo" joint="joint_left" kp="250" kv="25.0" ctrlrange="0 0.05" forcelimited="true" forcerange="-500 500" />
    <position name="joint_right_servo" joint="joint_right" kp="250" kv="25.0" ctrlrange="0 0.05" forcelimited="true" forcerange="-500 500" />
    -->
  </actuator>
</mujoco>